Workbook

Sheet 생산량표
N1: 생산량표
A2: <발송대기 데이터> | G2: 주문수량 정리 | N2: 오븐 | P2: 품명 | Q2: 총 판수 | R2: 삼각스콘 | Y2: 미니큐브 | AC2: 스틱스콘 | AF2: 생크림/판 | AG2: 생크림(총량)
A3: 관리명+옵션명 | B3: 상품명 | C3: 옵션 | D3: 수량 | G3: 구분 | H3: 관리명 | I3: 옵션 | J3: 주문수량 | N3: 삼각 / 바 | O3: 스/큐 | R3: 주문량 | S3: 이월재고 | T3: 판수 | U3: 판수 | V3: 남는량 | W3: 남는량 | X3: 판수 | Y3: 판수 | Z3: 이월재고(봉) | AA3: 남는량(봉) | AB3: 남는량(봉) | AC3: 판수 | AD3: 남는량(팩)
A4: =B4&C4 -> -------[Gourmet M]피넛머드[스무스] | B4: -------[Gourmet M]피넛머드 | C4: [스무스] | D4: 7 | G4: 츄러스콘 | H4: -통밀츄러스콘 | J4: =IFERROR(VLOOKUP(H4&I4,$A$3:$D$101,4,0),0) -> 250
A5: =B5&C5 -> -------소분용 OPP 봉투 20매[간식용] | B5: -------소분용 OPP 봉투 20매 | C5: [간식용] | D5: 1 | H5: ----[세트]통밀츄러스틱 3팩 | J5: =IFERROR(VLOOKUP(H5&I5,$A$3:$D$101,4,0),0) -> 8 | N5: 1 | O5: 4 | P5: 말차초코칩스콘 | Q5: =U5+AC5+Y5 -> 32 | R5: =J24 -> 252 | T5: =ROUNDUP(R5/8,0) -> 32 | U5: =IF(((AA5=1)*AND(V5>=4)),T5-0.5,T5+IF(AA5=1,0.5,0)) -> 32 | V5: =T5*8-R5 -> 4 | W5: =IF((V5+4*AA5)>=8,(V5+4*AA5)-8,(V5+4*AA5)) -> 4 | AF5: 170 | AG5: =Q5*AF5 -> 5440
A6: =B6&C6 -> -------소분용 OPP 봉투 20매[식사용] | B6: -------소분용 OPP 봉투 20매 | C6: [식사용] | D6: 6 | H6: -----[하프팩]통밀츄러미니큐브 | J6: =IFERROR(VLOOKUP(H6&I6,$A$3:$D$101,4,0),0) -> 4 | N6: 2 | O6: 4 | P6: 츄러스콘 | Q6: =U6+AC6+Y6 -> 37 | R6: =J4 -> 250 | T6: =ROUNDUP(R6/8,0) -> 32 | U6: =IF(((AA6=1)*AND(V6>=4)),T6-0.5,T6+IF(AA6=1,0.5,0)) -> 32 | V6: =T6*8-R6 -> 6 | W6: =IF((V6+4*AA6)>=8,(V6+4*AA6)-8,(V6+4*AA6)) -> 6 | X6: =ROUNDUP(J6/2,0) -> 2 | Y6: =IF(AA6=1,X6-0.5,X6) -> 2 | AA6: =X6*2-J6 -> 0 | AC6: =ROUNDUP((J49/9)+(J5/3),0) -> 3 | AD6: =(AC6*9-(J49+J5*3)) -> 0 | AF6: 174 | AG6: =Q6*AF6 -> 6438
A7: =B7&C7 -> ------YOF6팩 | B7: ------YOF6팩 | D7: 2 | G7: 데이츠 | H7: -데이츠치아씨드스콘 | J7: =IFERROR(VLOOKUP(H7&I7,$A$3:$D$101,4,0),0) -> 106 | N7: 11 | O7: 4 | P7: 데이츠치아씨드스콘 | Q7: =U7+AC7+Y7 -> 20 | R7: =J7 -> 106 | T7: =ROUNDUP(R7/8,0) -> 14 | U7: =IF(((AA7=1)*AND(V7>=4)),T7-0.5,T7+IF(AA7=1,0.5,0)) -> 13.5 | V7: =T7*8-R7 -> 6 | W7: =IF((V7+4*AA7)>=8,(V7+4*AA7)-8,(V7+4*AA7)) -> 2 | X7: =ROUNDUP(J9/2,0) -> 1 | Y7: =IF(AA7=1,X7-0.5,X7) -> 0.5 | AA7: =X7*2-J9 -> 1 | AC7: =ROUNDUP(J8/3,0) -> 6 | AD7: =(AC7*9-J8*3) -> 0 | AF7: 160 | AG7: =Q7*AF7 -> 3200
A8: =B8&C8 -> ------요프 한 가지 맛[ 말차] | B8: ------요프 한 가지 맛 | C8: [ 말차] | D8: 2 | H8: ----[세트]데치스틱 3팩 | J8: =IFERROR(VLOOKUP(H8&I8,$A$3:$D$101,4,0),0) -> 18 | N8: 4 | O8: 4 | P8: 바닐라피칸스콘 | Q8: =U8+AC8+Y8 -> 59 | R8: =J13 -> 358 | T8: =ROUNDUP(R8/8,0) -> 45 | U8: =IF(((AA8=1)*AND(V8>=4)),T8-0.5,T8+IF(AA8=1,0.5,0)) -> 45 | V8: =T8*8-R8 -> 2 | W8: =IF((V8+4*AA8)>=8,(V8+4*AA8)-8,(V8+4*AA8)) -> 2 | X8: =ROUNDUP(J15/2,0) -> 4 | Y8: =IF(AA8=1,X8-0.5,X8) -> 4 | AA8: =X8*2-J15 -> 0 | AC8: =ROUNDUP((J49/9)+(J14/3),0) -> 10 | AD8: =(AC8*9-(J49+J14*3)) -> 3 | AF8: 170 | AG8: =Q8*AF8 -> 10030
A9: =B9&C9 -> ------요프 한 가지 맛[ 쑥] | B9: ------요프 한 가지 맛 | C9: [ 쑥] | D9: 1 | H9: -----[하프팩]데치미니큐브 | J9: =IFERROR(VLOOKUP(H9&I9,$A$3:$D$101,4,0),0) -> 1 | N9: 7 | O9: 8 | P9: 버터밀크비스킷스콘 | Q9: =U9+AC9+Y9 -> 28 | R9: =J42 -> 155 | T9: =ROUNDUP(R9/8,0) -> 20 | U9: =IF(((AA9=1)*AND(V9>=4)),T9-0.5,T9+IF(AA9=1,0.5,0)) -> 19.5 | V9: =T9*8-R9 -> 5 | W9: =IF((V9+4*AA9)>=8,(V9+4*AA9)-8,(V9+4*AA9)) -> 1 | X9: =ROUNDUP(J44/2,0) -> 3 | Y9: =IF(AA9=1,X9-0.5,X9) -> 2.5 | AA9: =X9*2-J44 -> 1 | AC9: =ROUNDUP(J43/3,0) -> 6 | AD9: =(AC9*9-J43*3) -> 6 | AF9: 130 | AG9: =Q9*AF9 -> 3640
A10: =B10&C10 -> ------요프 한 가지 맛[ 콩가루] | B10: ------요프 한 가지 맛 | C10: [ 콩가루] | D10: 1 | G10: 카카오 | H10: -카카오스콘 | J10: =IFERROR(VLOOKUP(H10&I10,$A$3:$D$68,4,0),0) -> 193
A11: =B11&C11 -> -----[미니쉐이크]쑥인절미 | B11: -----[미니쉐이크]쑥인절미 | D11: 5 | H11: ----[세트]카카오스틱 3팩 | J11: =IFERROR(VLOOKUP(H11&I11,$A$3:$D$68,4,0),0) -> 19
A12: =B12&C12 -> -----[미니쉐이크]카카오파베 | B12: -----[미니쉐이크]카카오파베 | D12: 15 | H12: -----[하프팩]카카오미니큐브 | J12: =IFERROR(VLOOKUP(H12&I12,$A$3:$D$101,4,0),0) -> 5 | O12: 2 | P12: [미니쉐이크]쑥인절미 | Q12: =Y12 -> 2 | T12: =ROUNDUP(R12/8,0) -> 0 | V12: =T12*8-R12 -> 0 | X12: =ROUNDUP((J25+J49)/4,0) -> 2 | Y12: =IF(Z12>0,IF(AA12>=4,X12-1,X12),X12) -> 2 | AA12: =X12*4-J25-J49+Z12 -> 0 | AB12: =IF(Z12>0,IF(AA12>=4,AA12-4,AA12),AA12) -> 0 | AF12: 190 | AG12: =Q12*AF12 -> 380
A13: =B13&C13 -> -----[하프팩]OXO미니큐브 | B13: -----[하프팩]OXO미니큐브 | D13: 9 | G13: 바피 | H13: -바닐라피칸스콘 | J13: =IFERROR(VLOOKUP(H13&I13,$A$3:$D$101,4,0),0) -> 358 | N13: 1 | O13: 4 | P13: 데솔오트밀바 | Q13: =U13+AC13+Y13 -> 41 | R13: =J16 -> 293 | T13: =ROUNDUP(R13/8,0) -> 37 | U13: =IF(((AA13=1)*AND(V13>=5)),T13-0.5,T13+IF(AA13=1,0.5,0)) -> 37.5 | V13: =T13*8-R13 -> 3 | W13: =IF((V13+5*AA13)>=10,(V13+5*AA13)-10,(V13+5*AA13)) -> 8 | X13: =ROUNDUP(J17/2,0) -> 4 | Y13: =IF(AA13=1,X13-0.5,X13) -> 3.5 | AA13: =X13*2-J17 -> 1 | AF13: 160 | AG13: =Q13*AF13 -> 6560
A14: =B14&C14 -> -----[하프팩]귀초칩미니큐브 | B14: -----[하프팩]귀초칩미니큐브 | D14: 4 | H14: ----[세트]바닐라피칸스틱 3팩 | J14: =IFERROR(VLOOKUP(H14&I14,$A$3:$D$101,4,0),0) -> 28 | O14: 2 | P14: [미니쉐이크]카카오파베 | Q14: =Y14 -> 4 | T14: =ROUNDUP(R14/8,0) -> 0 | V14: =T14*8-R14 -> 0 | X14: =ROUNDUP((J26/4),0) -> 4 | Y14: =IF(Z14>0,IF(AA14>=4,X14-1,X14),X14) -> 4 | AA14: =X14*4-J26+Z14 -> 1 | AB14: =IF(Z14>0,IF(AA14>=4,AA14-4,AA14),AA14) -> 1 | AF14: 180 | AG14: =Q14*AF14 -> 720
A15: =B15&C15 -> -----[하프팩]더티너티밤미니큐브 | B15: -----[하프팩]더티너티밤미니큐브 | D15: 11 | H15: -----[하프팩]바닐라피칸미니큐브 | J15: =IFERROR(VLOOKUP(H15&I15,$A$3:$D$101,4,0),0) -> 8 | N15: 1 | O15: 2 | P15: 카카오스콘 | Q15: =U15+AC15+Y15 -> 34 | R15: =J10 -> 193 | T15: =ROUNDUP(R15/8,0) -> 25 | U15: =IF(((AA15=1)*AND(V15>=4)),T15-0.5,T15+IF(AA15=1,0.5,0)) -> 24.5 | V15: =T15*8-R15 -> 7 | W15: =IF((V15+4*AA15)>=8,(V15+4*AA15)-8,(V15+4*AA15)) -> 3 | X15: =ROUNDUP(J12/2,0) -> 3 | Y15: =IF(AA15=1,X15-0.5,X15) -> 2.5 | AA15: =X15*2-J12 -> 1 | AC15: =ROUNDUP(J11/3,0) -> 7 | AD15: =(AC15*9-J11*3) -> 6 | AF15: 180 | AG15: =Q15*AF15 -> 6120
A16: =B16&C16 -> -----[하프팩]데솔오바미니큐브 | B16: -----[하프팩]데솔오바미니큐브 | D16: 7 | G16: 데솔오바 | H16: -데솔오트밀바 | J16: =IFERROR(VLOOKUP(H16&I16,$A$3:$D$101,4,0),0) -> 293 | N16: 5 | O16: 8 | P16: OXO스콘 | Q16: =U16+AC16+Y16 -> 60 | R16: =J39+J49 -> 396 | T16: =ROUNDUP(R16/8,0) -> 50 | U16: =IF(((AA16=1)*AND(V16>=4)),T16-0.5,T16+IF(AA16=1,0.5,0)) -> 49.5 | V16: =T16*8-R16 -> 4 | W16: =IF((V16+4*AA16)>=8,(V16+4*AA16)-8,(V16+4*AA16)) -> 0 | X16: =ROUNDUP(J41/2,0) -> 5 | Y16: =IF(AA16=1,X16-0.5,X16) -> 4.5 | AA16: =X16*2-J41 -> 1 | AC16: =ROUNDUP(J40/3,0) -> 6 | AD16: =(AC16*9-J40*3) -> 3 | AF16: 150 | AG16: =Q16*AF16 -> 9000
A17: =B17&C17 -> -----[하프팩]데치미니큐브 | B17: -----[하프팩]데치미니큐브 | D17: 1 | H17: -----[하프팩]데솔오바미니큐브 | J17: =IFERROR(VLOOKUP(H17&I17,$A$3:$D$101,4,0),0) -> 7 | N17: 5 | O17: 8 | P17: 순수오트스콘 | Q17: =U17+AC17+Y17 -> 12 | R17: =J20 -> 87 | T17: =ROUNDUP(R17/8,0) -> 11 | U17: =IF(((AA17=1)*AND(V17>=4)),T17-0.5,T17+IF(AA17=1,0.5,0)) -> 11.5 | V17: =T17*8-R17 -> 1 | W17: =IF((V17+4*AA17)>=8,(V17+4*AA17)-8,(V17+4*AA17)) -> 5 | X17: =ROUNDUP(J21/2,0) -> 1 | Y17: =IF(AA17=1,X17-0.5,X17) -> 0.5 | AA17: =X17*2-J21 -> 1 | AF17: 140 | AG17: =Q17*AF17 -> 1680
A18: =B18&C18 -> -----[하프팩]말차오트초코칩미니큐브 | B18: -----[하프팩]말차오트초코칩미니큐브 | D18: 5 | G18: 귀초칩 | H18: -귀리초코칩스콘 | J18: =IFERROR(VLOOKUP(H18&I18,$A$3:$D$101,4,0),0) -> 219 | N18: 1 | O18: 4 | P18: 귀리초코칩스콘 | Q18: =U18+AC18+Y18 -> 30 | R18: =J18+J49 -> 222 | T18: =ROUNDUP(R18/8,0) -> 28 | U18: =IF(((AA18=1)*AND(V18>=4)),T18-0.5,T18+IF(AA18=1,0.5,0)) -> 28 | V18: =T18*8-R18 -> 2 | W18: =IF((V18+4*AA18)>=8,(V18+4*AA18)-8,(V18+4*AA18)) -> 2 | X18: =ROUNDUP(J19/2,0) -> 2 | Y18: =IF(AA18=1,X18-0.5,X18) -> 2 | AA18: =X18*2-J19 -> 0 | AF18: 180 | AG18: =Q18*AF18 -> 5400
A19: =B19&C19 -> -----[하프팩]바닐라피칸미니큐브 | B19: -----[하프팩]바닐라피칸미니큐브 | D19: 8 | H19: -----[하프팩]귀초칩미니큐브 | J19: =IFERROR(VLOOKUP(H19&I19,$A$3:$D$101,4,0),0) -> 4 | N19: 7 | O19: 7 | P19: 딥카카오트스콘 | Q19: =U19+AC19+Y19 -> 0 | R19: =J52 -> 0 | T19: =ROUNDUP(R19/8,0) -> 0 | U19: =IF(((AA19=1)*AND(V19>=4)),T19-0.5,T19+IF(AA19=1,0.5,0)) -> 0 | V19: =T19*8-R19 -> 0 | W19: =IF((V19+4*AA19)>=8,(V19+4*AA19)-8,(V19+4*AA19)) -> 0 | X19: =ROUNDUP(J53/2,0) -> 0 | Y19: =IF(AA19=1,X19-0.5,X19) -> 0 | AA19: =X19*2-J53 -> 0 | AF19: 130 | AG19: =Q19*AF19 -> 0
A20: =B20&C20 -> -----[하프팩]버터밀크비스킷미니큐브 | B20: -----[하프팩]버터밀크비스킷미니큐브 | D20: 5 | G20: 순수오트 | H20: -순수오트스콘 | J20: =IFERROR(VLOOKUP(H20&I20,$A$3:$D$101,4,0),0) -> 87 | N20: 7 | O20: 8 | P20: 더티너티밤스콘 | Q20: =U20+AC20+Y20 -> 72 | R20: =J46 -> 429 | T20: =ROUNDUP(R20/8,0) -> 54 | U20: =IF(((AA20=1)*AND(V20>=4)),T20-0.5,T20+IF(AA20=1,0.5,0)) -> 54.5 | V20: =T20*8-R20 -> 3 | W20: =IF((V20+4*AA20)>=8,(V20+4*AA20)-8,(V20+4*AA20)) -> 7 | X20: =ROUNDUP(J48/2,0) -> 6 | Y20: =IF(AA20=1,X20-0.5,X20) -> 5.5 | AA20: =X20*2-J48 -> 1 | AC20: =ROUNDUP(J47/3,0) -> 12 | AD20: =(AC20*9-J47*3) -> 6 | AF20: 110 | AG20: =Q20*AF20 -> 7920
A21: =B21&C21 -> -----[하프팩]베리초코칩미니큐브 | B21: -----[하프팩]베리초코칩미니큐브 | D21: 6 | H21: -----[하프팩]순수오트미니큐브 | J21: =IFERROR(VLOOKUP(H21&I21,$A$3:$D$101,4,0),0) -> 1 | N21: 7 | O21: 8 | P21: 말차오트초코칩스콘 | Q21: =U21+AC21+Y21 -> 17 | R21: =J50 -> 109 | T21: =ROUNDUP(R21/8,0) -> 14 | U21: =IF(((AA21=1)*AND(V21>=4)),T21-0.5,T21+IF(AA21=1,0.5,0)) -> 14.5 | V21: =T21*8-R21 -> 3 | W21: =IF((V21+4*AA21)>=8,(V21+4*AA21)-8,(V21+4*AA21)) -> 7 | X21: =ROUNDUP(J51/2,0) -> 3 | Y21: =IF(AA21=1,X21-0.5,X21) -> 2.5 | AA21: =X21*2-J51 -> 1 | AF21: 125 | AG21: =Q21*AF21 -> 2125
A22: =B22&C22 -> -----[하프팩]순수오트미니큐브 | B22: -----[하프팩]순수오트미니큐브 | D22: 1 | G22: 베리초코 | H22: -베리초코칩스콘 | J22: =IFERROR(VLOOKUP(H22&I22,$A$3:$D$101,4,0),0) -> 137 | N22: 7 | O22: 8 | P22: 베리초코칩스콘 | Q22: =U22+AC22+Y22 -> 21 | R22: =J22 -> 137 | T22: =ROUNDUP(R22/8,0) -> 18 | U22: =IF(((AA22=1)*AND(V22>=4)),T22-0.5,T22+IF(AA22=1,0.5,0)) -> 18 | V22: =T22*8-R22 -> 7 | W22: =IF((V22+4*AA22)>=8,(V22+4*AA22)-8,(V22+4*AA22)) -> 7 | X22: =ROUNDUP(J23/2,0) -> 3 | Y22: =IF(AA22=1,X22-0.5,X22) -> 3 | AA22: =X22*2-J23 -> 0 | AF22: 140 | AG22: =Q22*AF22 -> 2940
A23: =B23&C23 -> -----[하프팩]카카오미니큐브 | B23: -----[하프팩]카카오미니큐브 | D23: 5 | H23: -----[하프팩]베리초코칩미니큐브 | J23: =IFERROR(VLOOKUP(H23&I23,$A$3:$D$101,4,0),0) -> 6
A24: =B24&C24 -> -----[하프팩]통밀츄러미니큐브 | B24: -----[하프팩]통밀츄러미니큐브 | D24: 4 | G24: 말초 | H24: -말차초코칩스콘 | J24: =IFERROR(VLOOKUP(H24&I24,$A$3:$D$101,4,0),0) -> 252 | P24: 스콘 합계 | Q24: ="총 " & SUM(Q4:Q23) & "판" -> 총 469판 | T24: =SUM(T4:T23) -> 380 | U24: =SUM(U4:U23) -> 380 | W24: =SUM(W4:W23) -> 54 | X24: =SUM(X4:X23) -> 43 | Y24: =SUM(Y4:Y23) -> 39 | AC24: =SUM(AC4:AC23) -> 50 | AD24: =SUM(AD4:AD23) -> 24
A25: =B25&C25 -> ----[세트]OXO스틱 3팩 | B25: ----[세트]OXO스틱 3팩 | D25: 17 | H25: -----[미니쉐이크]쑥인절미 | J25: =IFERROR(VLOOKUP(H25&I25,$A$3:$D$101,4,0),0) -> 5
A26: =B26&C26 -> ----[세트]더티너티밤스틱 3팩 | B26: ----[세트]더티너티밤스틱 3팩 | D26: 34 | H26: -----[미니쉐이크]카카오파베 | J26: =IFERROR(VLOOKUP(H26&I26,$A$3:$D$101,4,0),0) -> 15 | O26: 휩드생크림 | Q26: 발송건수 | S26: OPP(식사) | T26: 그릭요거트 | U26: 대파분태 | V26: 스무스 | Y26: 크런치
A27: =B27&C27 -> ----[세트]데치스틱 3팩 | B27: ----[세트]데치스틱 3팩 | D27: 18 | H27: ------YOF6팩 | J27: =IFERROR(VLOOKUP(H27&I27,$A$3:$D$101,4,0),0) -> 2 | O27: =ROUNDUP(SUM(AG4:AG26)/1000,0) -> 72 | S27: =J36 -> 0 | T27: =J33 -> 0 | U27: =J32 -> 0 | V27: =J34 -> 7 | Y27: =J35 -> 0
A28: =B28&C28 -> ----[세트]바닐라피칸스틱 3팩 | B28: ----[세트]바닐라피칸스틱 3팩 | D28: 28 | H28: ------요프 한 가지 맛 | I28: [단호박] | J28: =IFERROR(VLOOKUP(H28&I28,$A$3:$D$101,4,0),0) -> 0 | O28: 서비스수량 | P28: 추가량 + 남는량 | Q28: 부족 서비스 | R28: 남는 서비스 | S28: 이매진 | T28: 종이가방 | U28: 스타터팩 | V28: 파베(봉) | Y28: 인절미(봉)
A29: =B29&C29 -> ----[세트]버터밀크비스킷스틱 3팩 | B29: ----[세트]버터밀크비스킷스틱 3팩 | D29: 16 | H29: ------요프 한 가지 맛 | I29: [ 말차] | J29: =IFERROR(VLOOKUP(H29&I29,$A$3:$D$101,4,0),0) -> 2 | O29: =J45 -> 110 | P29: =W24+AD24 -> 78 | Q29: =IF(O29-P29>=0,O29-P29,"없음") -> 32 | R29: =IF(O29-P29<0,-(O29-P29),"없음") -> 없음 | S29: =J37 -> 0 | T29: =J38 -> 0 | U29: =J49 -> 3 | V29: =J26 -> 15 | Y29: =J25+J49 -> 8
A30: =B30&C30 -> ----[세트]카카오스틱 3팩 | B30: ----[세트]카카오스틱 3팩 | D30: 19 | H30: ------요프 한 가지 맛 | I30: [ 콩가루] | J30: =IFERROR(VLOOKUP(H30&I30,$A$3:$D$101,4,0),0) -> 1
A31: =B31&C31 -> ----[세트]통밀츄러스틱 3팩 | B31: ----[세트]통밀츄러스틱 3팩 | D31: 8 | H31: ------요프 한 가지 맛 | I31: [ 흑임자] | J31: =IFERROR(VLOOKUP(H31&I31,$A$3:$D$101,4,0),0) -> 0
A32: =B32&C32 -> ---단호박스콘 | B32: ---단호박스콘 | D32: 238 | H32: ------대파분태 | J32: =IFERROR(VLOOKUP(H32&I32,$A$3:$D$101,4,0),0) -> 0 | AH32: 상품명 | AI32: 오븐번호 | AJ32: 삼각(바)판수 | AK32: 풀팬 | AL32: 풀팬(3판) | AM32: 남는 반죽 판수 | AN32: 남는 반죽 판수
A33: =B33&C33 -> ---쑥스콘 | B33: ---쑥스콘 | D33: 140 | H33: -----GREEK YOGURT | J33: =IFERROR(VLOOKUP(H33&I33,$A$3:$D$101,4,0),0) -> 0 | AH33: 말차초코칩스콘 | AI33: =_xlfn.XLOOKUP(AH33,$P$4:$P$23,$N$4:$N$23,"N/A",0) -> 1 | AJ33: =_xlfn.XLOOKUP(AH33,$P$4:$P$23,$U$4:$U$23,"NA",0) -> 32 | AK33: =ROUNDDOWN(AJ33/3,0) -> 10 | AL33: =IF(AK33>0,IF((AM33>0)*AND((AK33)>1),AK33-1,AK33),AK33) -> 9 | AM33: =AJ33-(3*AK33) -> 2 | AN33: =3*(AK33-AL33)+AM33 -> 5
A34: =B34&C34 -> ---쑥인절미꿀호떡스콘 | B34: ---쑥인절미꿀호떡스콘 | D34: 129 | H34: -------[Gourmet M]피넛머드 | I34: [스무스] | J34: =IFERROR(VLOOKUP(H34&I34,$A$3:$D$101,4,0),0) -> 7 | AH34: 츄러스콘 | AI34: =_xlfn.XLOOKUP(AH34,$P$4:$P$23,$N$4:$N$23,"N/A",0) -> 2 | AJ34: =_xlfn.XLOOKUP(AH34,$P$4:$P$23,$U$4:$U$23,"NA",0) -> 32 | AK34: =ROUNDDOWN(AJ34/3,0) -> 10 | AL34: =IF(AK34>0,IF((AM34>0)*AND((AK34)>1),AK34-1,AK34),AK34) -> 9 | AM34: =AJ34-(3*AK34) -> 2 | AN34: =3*(AK34-AL34)+AM34 -> 5
A35: =B35&C35 -> ---흑미밤설기바스콘 | B35: ---흑미밤설기바스콘 | D35: 103 | H35: -------[Gourmet M]피넛머드 | I35: [크런치] | J35: =IFERROR(VLOOKUP(H35&I35,$A$3:$D$101,4,0),0) -> 0 | AH35: 데이츠치아씨드스콘 | AI35: =_xlfn.XLOOKUP(AH35,$P$4:$P$23,$N$4:$N$23,"N/A",0) -> 11 | AJ35: =_xlfn.XLOOKUP(AH35,$P$4:$P$23,$U$4:$U$23,"NA",0) -> 13.5 | AK35: =ROUNDDOWN(AJ35/3,0) -> 4 | AL35: =IF(AK35>0,IF((AM35>0)*AND((AK35)>1),AK35-1,AK35),AK35) -> 3 | AM35: =AJ35-(3*AK35) -> 1.5 | AN35: =3*(AK35-AL35)+AM35 -> 4.5
A36: =B36&C36 -> ---흑임자라떼스콘 | B36: ---흑임자라떼스콘 | D36: 100 | H36: -------소분용 OPP 봉투 20매 | I36: [식사용] | J36: =IFERROR(VLOOKUP(H36&I36,$A$3:$D$101,4,0),0) -> 0 | AH36: 바닐라피칸스콘 | AI36: =_xlfn.XLOOKUP(AH36,$P$4:$P$23,$N$4:$N$23,"N/A",0) -> 4 | AJ36: =_xlfn.XLOOKUP(AH36,$P$4:$P$23,$U$4:$U$23,"NA",0) -> 45 | AK36: =ROUNDDOWN(AJ36/3,0) -> 15 | AL36: =IF(AK36>0,IF((AM36>0)*AND((AK36)>1),AK36-1,AK36),AK36) -> 15 | AM36: =AJ36-(3*AK36) -> 0 | AN36: =3*(AK36-AL36)+AM36 -> 0
A37: =B37&C37 -> -OXO스콘 | B37: -OXO스콘 | D37: 393 | H37: 이매진 머드 | J37: =IFERROR(VLOOKUP(H37&I37,$A$3:$D$101,4,0),0) -> 0 | AH37: 버터밀크비스킷스콘 | AI37: =_xlfn.XLOOKUP(AH37,$P$4:$P$23,$N$4:$N$23,"N/A",0) -> 7 | AJ37: =_xlfn.XLOOKUP(AH37,$P$4:$P$23,$U$4:$U$23,"NA",0) -> 19.5 | AK37: =ROUNDDOWN(AJ37/3,0) -> 6 | AL37: =IF(AK37>0,IF((AM37>0)*AND((AK37)>1),AK37-1,AK37),AK37) -> 5 | AM37: =AJ37-(3*AK37) -> 1.5 | AN37: =3*(AK37-AL37)+AM37 -> 4.5
A38: =B38&C38 -> -귀리초코칩스콘 | B38: -귀리초코칩스콘 | D38: 219 | H38: -------선물용 종이가방 | J38: =IFERROR(VLOOKUP(H38&I38,$A$3:$D$101,4,0),0) -> 0
A39: =B39&C39 -> -더티너티밤스콘 | B39: -더티너티밤스콘 | D39: 429 | G39: OXO | H39: -OXO스콘 | J39: =IFERROR(VLOOKUP(H39&I39,$A$3:$D$101,4,0),0) -> 393
A40: =B40&C40 -> -데솔오트밀바 | B40: -데솔오트밀바 | D40: 293 | H40: ----[세트]OXO스틱 3팩 | J40: =IFERROR(VLOOKUP(H40&I40,$A$3:$D$101,4,0),0) -> 17 | AH40: 데솔오트밀바 | AI40: =_xlfn.XLOOKUP(AH40,$P$4:$P$23,$N$4:$N$23,"N/A",0) -> 1 | AJ40: =_xlfn.XLOOKUP(AH40,$P$4:$P$23,$U$4:$U$23,"NA",0) -> 37.5 | AK40: =ROUNDDOWN(AJ40/3,0) -> 12 | AL40: =IF(AK40>0,IF((AM40>0)*AND((AK40)>1),AK40-1,AK40),AK40) -> 11 | AM40: =AJ40-(3*AK40) -> 1.5 | AN40: =3*(AK40-AL40)+AM40 -> 4.5
...

Sheet 발송특이사항
A1: 발송 특이사항 0000()
A2: [서비스스콘] | C2: * 서비스스콘은 모두 선반영 완료
A3: VIP | B3: 사고건 | C3: 무배 | D3: 직원
E4: 합=> | F4: =SUM(A4:D4) -> 0
A5: [특이사항]
A9: [픽업]
A12: [제주도 >> 로젠택배]
A15: [그릭요거트] | E15: [YoF-6] | H15: [YoF-1]
A17: 수량 | B17: 주문건수 | C17: 주문수량 | E17: 수량 | F17: 주문건 | H17: 종류 | I17: 수량
A18: 1 | B18: =COUNTIF('그릭요거트 '!$A$2:A$999,"1") -> 0 | C18: =A18*B18 -> 0 | E18: 1개 | F18: =YOF!D2 -> 0 | H18: 단호박 | I18: =(생산량표!J28) -> 0
A19: 2 | B19: =COUNTIF('그릭요거트 '!$A$2:A$999,"2") -> 0 | C19: =A19*B19 -> 0 | E19: 2개 | F19: =YOF!D3+YOF!D5+YOF!D6+YOF!D9+YOF!D11+YOF!D14+YOF!D16+YOF!D19+YOF!D21+YOF!D24+YOF!D26+YOF!D29+YOF!D31 -> 0 | H19: 말차 | I19: =(생산량표!J29) -> 2
A20: 3 | B20: =COUNTIF('그릭요거트 '!$A$2:A$999,"3") -> 0 | C20: =A20*B20 -> 0 | E20: 3개 | F20: =YOF!D4+YOF!D7+YOF!D8+YOF!D10+YOF!D12+YOF!D13+YOF!D15+YOF!D17+YOF!D18+YOF!D20+YOF!D22+YOF!D23+YOF!D25+YOF!D27+YOF!D28+YOF!D30+YOF!D32 -> 0 | H20: 콩가루 | I20: =(생산량표!J30) -> 1
A21: 4 | B21: =COUNTIF('그릭요거트 '!$A$2:A$999,"4") -> 0 | C21: =A21*B21 -> 0 | E21: 합계 | F21: =SUM(F18:F20) -> 0 | H21: 흑임자 | I21: =(생산량표!J31) -> 0
A22: 5 | B22: =COUNTIF('그릭요거트 '!$A$2:A$999,"5") -> 0 | C22: =A22*B22 -> 0 | H22: 합계 | I22: =SUM(I18:I21) -> 3
A23: 6 | B23: =COUNTIF('그릭요거트 '!$A$2:A$999,"6") -> 0 | C23: =A23*B23 -> 0
A24: 7 | B24: =COUNTIF('그릭요거트 '!$A$2:A$999,"7") -> 0 | C24: =A24*B24 -> 0
A25: 8 | B25: =COUNTIF('그릭요거트 '!$A$2:A$999,"8") -> 0 | C25: =A25*B25 -> 0
A26: 9 | B26: =COUNTIF('그릭요거트 '!$A$2:A$999,"9") -> 0 | C26: =A26*B26 -> 0
A27: 10 | B27: =COUNTIF('그릭요거트 '!$A$2:A$999,"10") -> 0 | C27: =A27*B27 -> 0
A28: 합계 | B28: =SUM(B18:B27) -> 0 | C28: =SUM(C18:C27) -> 0
A30: 발송건수 : | B30: =생산량표!Q27 -> 0 | C30: 건

Sheet 그릭요거트 
A1: 요거트갯수

Sheet YOF
A1: 수량 | B1: 주문건수 | C1: 봉투내 수량 | D1: 봉투수량(유통기한 스티커 수) | E1: 유통기한 | G1: 요프 수량
A2: 1개 | B2: =COUNTIF(G1:G501,"1") -> 0 | C2: 1개*1봉 | D2: =B2 -> 0
A3: 2개 | B3: =COUNTIF(G1:G501,"2") -> 0 | C3: 2개*1봉 | D3: =B3 -> 0
A4: 3개 | B4: =COUNTIF(G1:G501,"3") -> 0 | C4: 3개*1봉 | D4: =B4 -> 0
A5: 4개 | B5: =COUNTIF(G1:G501,"4") -> 0 | C5: 2개*2봉 | D5: =B5*2 -> 0
A6: 5개 | B6: =COUNTIF(G1:G501,"5") -> 0 | C6: 2개*1봉 | D6: =B6 -> 0
C7: 3개*1봉 | D7: =B6 -> 0
A8: 6개 | B8: =COUNTIF(G1:G501,"6") -> 0 | C8: 3개*2봉 | D8: =B8*2 -> 0
A9: 7개 | B9: =COUNTIF(G1:G501,"7") -> 0 | C9: 2개*2봉 | D9: =B9*2 -> 0
C10: 3개*1봉 | D10: =B9 -> 0
A11: 8개 | B11: =COUNTIF(G1:G501,"8") -> 0 | C11: 2개*1봉 | D11: =B11 -> 0
C12: 3개*2봉 | D12: =B11*2 -> 0
A13: 9개 | B13: =COUNTIF(G1:G501,"9") -> 0 | C13: 3개*3봉 | D13: =B13*3 -> 0
A14: 10개 | B14: =COUNTIF(G1:G501,"10") -> 0 | C14: 2개*2봉 | D14: =B14*2 -> 0
C15: 3개*2봉 | D15: =B14*2 -> 0
A16: 11개 | B16: =COUNTIF(G1:G501,"11") -> 0 | C16: 2개*1봉 | D16: =B16 -> 0
C17: 3개*3봉 | D17: =B16*3 -> 0
A18: 12개 | B18: =COUNTIF(G1:G501,"12") -> 0 | C18: 3개*4봉 | D18: =B18*4 -> 0
A19: 13개 | B19: =COUNTIF(G1:G501,"13") -> 0 | C19: 2개*2봉 | D19: =B19*2 -> 0
C20: 3개*3봉 | D20: =B19*3 -> 0
A21: 14개 | B21: =COUNTIF(G1:G501,"14") -> 0 | C21: 2개*1봉 | D21: =B21*1 -> 0
C22: 3개*4봉 | D22: =B21*4 -> 0
A23: 15개 | B23: =COUNTIF(G1:G501,"15") -> 0 | C23: 3개*5봉 | D23: =B23*5 -> 0
A24: 16개 | B24: =COUNTIF(G1:G501,"16") -> 0 | C24: 2개*2봉 | D24: =B24*2 -> 0
C25: 3개*4봉 | D25: =B24*4 -> 0
A26: 17개 | B26: =COUNTIF(G1:G501,"17") -> 0 | C26: 2개*1봉 | D26: =B26*1 -> 0
C27: 3개*5봉 | D27: =B26*5 -> 0
A28: 18개 | B28: =COUNTIF(G1:G501,"18") -> 0 | C28: 3개*6봉 | D28: =B28*6 -> 0
A29: 19개 | B29: =COUNTIF(G1:G501,"19") -> 0 | C29: 2개*2봉 | D29: =B29*2 -> 0
C30: 3개*5봉 | D30: =B29*5 -> 0
A31: 20개 | B31: =COUNTIF(G1:G501,"20") -> 0 | C31: 2개*1봉 | D31: =B31*1 -> 0
C32: 3개*6봉 | D32: =B31*6 -> 0
A33: 합계 | B33: =SUM(B2:B32) -> 0 | D33: =SUM(D2:D32) -> 0
